Workbook

Sheet 01_Resumen_Portafolio
A1: UNIVERSIDAD NACIONAL DE INGENIERÍA - FACULTAD DE INGENIERÍA CIVIL | M1: Código: CASA-TP-26
A2: MAESTRÍA EN GESTIÓN Y DIRECCIÓN DE EMPRESAS DE LA CONSTRUCCIÓN (DAC) | M2: Fecha: 23/10/2026
A3: TALLER N°07 · GESTIÓN ESTRATÉGICA DE PORTAFOLIOS DE PROYECTOS (CASA-TP-26 / GRUPO N°04) | M3: Versión: 01
A4: DOCENTE: ING. ALFONSO NÚÑEZ, MBA, PMP® · ALUMNOS: GRUPO 04
M5: Página: 1 de 8
A7: TABLA 01: MATRIZ MAESTRA DE LOS 10 MEGAPROYECTOS DE CASA CONTRATISTAS (2026 - 2034)
A8: N° | B8: Código | C8: Nombre del Megaproyecto | D8: Macrorregión | E8: Categoría PMI | F8: Periodo Contractual | G8: Inversión (Soles) | H8: Inversión (USD M) | I8: Estatus Operativo | J8: TIR (%) | K8: VAN (S/ Millones) | L8: ROI Estimado | M8: Alineación (1-3) | N8: Riesgo (0-3) | O8: Sponsor / Entidad Mandante
A9: 1 | B9: CASA-26-VIA-001 | C9: Autopista del Sol (Trujillo - Sullana) | D9: Costa | E9: Estratégico | F9: 2009 - 2034 | G9: 1471875000 | H9: 392.5 | I9: En Operación | J9: 0.145 | K9: 450 | L9: 12 - 15% | M9: ='02_Alineacion_Estrategica'!D21 -> 2.6 | N9: ='03_Evaluacion_Riesgos'!C17 -> 1.9 | O9: MTC / OSITRAN / COVISOL
A10: 2 | B10: CASA-26-VIA-002 | C10: Interoceánica Sur Tramo 5 (IIRSA Sur) | D10: Sierra | E10: Estratégico | F10: 2007 - 2022 | G10: 975000000 | H10: 260 | I10: Concluido | J10: 0.138 | K10: 320 | L10: 11 - 14% | M10: ='02_Alineacion_Estrategica'!E21 -> 2.38 | N10: ='03_Evaluacion_Riesgos'!C18 -> 2.1 | O10: MTC / Provías Nacional
A11: 3 | B11: CASA-26-VIA-003 | C11: Red Vial N.º 6 (Pucusana - Ica) | D11: Costa | E11: Estratégico | F11: 2006 - 2031 | G11: 487500000 | H11: 130 | I11: En Operación | J11: 0.152 | K11: 210 | L11: 13 - 16% | M11: ='02_Alineacion_Estrategica'!F21 -> 2.48 | N11: ='03_Evaluacion_Riesgos'!C19 -> 1.85 | O11: MTC / OSITRAN / COVIPERÚ
A12: 4 | B12: CASA-26-VIA-004 | C12: Segunda Calzada Puno - Juliaca | D12: Sierra | E12: Estratégico | F12: 2015 - 2029 | G12: 260000000 | H12: 69.3 | I12: En Ejecución | J12: 0.115 | K12: 85 | L12: 9 - 12% | M12: ='02_Alineacion_Estrategica'!G21 -> 2.23 | N12: ='03_Evaluacion_Riesgos'!C20 -> 1.6 | O12: MTC / Provías Nacional
A13: 5 | B13: CASA-26-POR-005 | C13: Terminal Portuario Yurimaguas (Nueva Presencia) | D13: Selva | E13: Estratégico | F13: 2011 - 2041 | G13: 35625000 | H13: 9.5 | I13: En Operación | J13: 0.12 | K13: 28 | L13: 10 - 13% | M13: ='02_Alineacion_Estrategica'!H21 -> 2.15 | N13: ='03_Evaluacion_Riesgos'!C21 -> 1.95 | O13: APN / COPAM / MTC
A14: 6 | B14: CASA-26-HID-006 | C14: Obras de Irrigación Amojao (10,000 ha) | D14: Selva | E14: Sostenibilidad | F14: 2016 - 2028 | G14: 47650000 | H14: 12.7 | I14: En Ejecución | J14: 0.108 | K14: 35 | L14: 8 - 11% | M14: ='02_Alineacion_Estrategica'!I21 -> 2.15 | N14: ='03_Evaluacion_Riesgos'!C22 -> 1.75 | O14: MINAGRI / PEJSIB
A15: 7 | B15: CASA-26-VIA-007 | C15: Red Vial Huallaga (Tocache - Tingo María) | D15: Selva | E15: Táctico | F15: 2017 - 2022 | G15: 16000000 | H15: 4.3 | I15: Concluido | J15: 0.14 | K15: 18 | L15: 12 - 15% | M15: ='02_Alineacion_Estrategica'!J21 -> 2.15 | N15: ='03_Evaluacion_Riesgos'!C23 -> 1.5 | O15: Provías Nacional
A16: 8 | B16: CASA-26-VIA-008 | C16: Conservación Pampa Pejerrey | D16: Costa | E16: Táctico | F16: 2018 - 2021 | G16: 26000000 | H16: 6.9 | I16: Concluido | J16: 0.135 | K16: 14 | L16: 11 - 13% | M16: ='02_Alineacion_Estrategica'!K21 -> 2 | N16: ='03_Evaluacion_Riesgos'!C24 -> 1.3 | O16: Provías Zonal Ica-Huancavelica
A17: 9 | B17: CASA-26-HID-009 | C17: Presa Poechos (Cuenco Amortiguador) | D17: Costa | E17: Sostenibilidad | F17: 2019 - 2021 | G17: 64625000 | H17: 17.2 | I17: Concluido | J17: 0.125 | K17: 42 | L17: 10 - 12% | M17: ='02_Alineacion_Estrategica'!L21 -> 2 | N17: ='03_Evaluacion_Riesgos'!C25 -> 1.4 | O17: Gob. Reg. Piura / PECHP
A18: 10 | B18: CASA-26-SAN-010 | C18: Agua Potable y PTAP Piura - Castilla | D18: Costa | E18: Sostenibilidad | F18: 2021 - 2023 | G18: 250000000 | H18: 66.7 | I18: Concluido | J18: 0.095 | K18: 65 | L18: 7 - 10% | M18: ='02_Alineacion_Estrategica'!M21 -> 1.92 | N18: ='03_Evaluacion_Riesgos'!C26 -> 1.2 | O18: MVCS / EPS Grau
A20: CÁLCULOS ESTADÍSTICOS CONSOLIDADOS DEL PORTAFOLIO
A21: Total Inversión Consolidada (Soles) | G21: =SUM(G9:G18) -> 3634275000 | H21: =SUM(H9:H18) -> 969.1 | I21: Suma Total
A22: Promedio Aritmético por Proyecto | G22: =AVERAGE(G9:G18) -> 363427500 | H22: =AVERAGE(H9:H18) -> 96.91 | I22: Media | J22: =AVERAGE(J9:J18) -> 0.1273 | K22: =AVERAGE(K9:K18) -> 126.7 | M22: =AVERAGE(M9:M18) -> 2.206 | N22: =AVERAGE(N9:N18) -> 1.655
A23: Mediana del Presupuesto | G23: =MEDIAN(G9:G18) -> 157312500 | H23: =MEDIAN(H9:H18) -> 41.95
A24: Desviación Estándar (muestral) | G24: =_xlfn.STDEV.S(G9:G18) -> 4.9133038e+08 | H24: =_xlfn.STDEV.S(H9:H18) -> 131.02401
A25: Inversión Mínima | G25: =MIN(G9:G18) -> 16000000 | H25: =MIN(H9:H18) -> 4.3
A26: Inversión Máxima | G26: =MAX(G9:G18) -> 1471875000 | H26: =MAX(H9:H18) -> 392.5
A27: Total VAN Acumulado (S/ M) | K27: =SUM(K9:K18) -> 1267
A29: DISTRIBUCIÓN POR CATEGORÍA ESTRATÉGICA
A30: Categoría | B30: Cantidad Proyectos | C30: Fórmula Conteo | D30: Inversión Total (S/) | E30: % Presupuesto
A31: Estratégico | B31: =COUNTIF(E9:E18, "Estratégico") -> 5 | C31: =COUNTIF($E$9:$E$18,A31) -> 5 | D31: =SUMIF(E9:E18, "Estratégico", G9:G18) -> 3230000000 | E31: =D31/$G$21 -> 0.88876048
A32: Sostenibilidad | B32: =COUNTIF(E9:E18, "Sostenibilidad") -> 3 | C32: =COUNTIF($E$9:$E$18,A32) -> 3 | D32: =SUMIF(E9:E18, "Sostenibilidad", G9:G18) -> 362275000 | E32: =D32/$G$21 -> 0.09968288
A33: Táctico | B33: =COUNTIF(E9:E18, "Táctico") -> 2 | C33: =COUNTIF($E$9:$E$18,A33) -> 2 | D33: =SUMIF(E9:E18, "Táctico", G9:G18) -> 42000000 | E33: =D33/$G$21 -> 0.011556638
A34: TOTAL | B34: =SUM(B31:B33) -> 10 | C34: =SUM(C31:C33) -> 10 | D34: =SUM(D31:D33) -> 3634275000 | E34: =SUM(E31:E33) -> 1
A36: DISTRIBUCIÓN POR MACRORREGIÓN
A37: Región Geográfica | B37: Cantidad | C37: Inversión Total (S/) | D37: % Participación
A38: Costa | B38: =COUNTIF(D9:D18, "Costa") -> 5 | C38: =SUMIF(D9:D18, "Costa", G9:G18) -> 2300000000 | D38: =C38/$G$21 -> 0.6328635
A39: Sierra | B39: =COUNTIF(D9:D18, "Sierra") -> 2 | C39: =SUMIF(D9:D18, "Sierra", G9:G18) -> 1235000000 | D39: =C39/$G$21 -> 0.33982018
A40: Selva | B40: =COUNTIF(D9:D18, "Selva") -> 3 | C40: =SUMIF(D9:D18, "Selva", G9:G18) -> 99275000 | D40: =C40/$G$21 -> 0.027316315
A41: TOTAL | B41: =SUM(B38:B40) -> 10 | C41: =SUM(C38:C40) -> 3634275000 | D41: =SUM(D38:D40) -> 1

Sheet 02_Alineacion_Estrategica
A1: MÓDULO 03 / TALLER 07: MATRIZ DE ALINEACIÓN ESTRATÉGICA DETALLADA | K1: Código: CASA-TP-26
A2: METODOLOGÍA DE EVALUACIÓN MULTICRITERIO PONDERADA (ESCALA: 1 = NO CONTRIBUYE, 2 = CONTRIBUCIÓN MEDIA <50%, 3 = CONTRIBUCIÓN ALTA >50%) | K2: Fecha: 23/10/2026
A3: FÓRMULA EXCEL DE ALINEACIÓN PONDERADA: =SUMPRODUCT(PESOS, NOTAS) / SUM(PESOS) | K3: Versión: 01
K4: Página: 2 de 8
A5: ID | B5: Peso (W) | C5: Objetivo Estratégico Corporativo CASA | D5: P1 Autopista | E5: P2 IIRSA T5 | F5: P3 Red Vial 6 | G5: P4 Puno-Jul | H5: P5 Yurimag | I5: P6 Amojao | J5: P7 Huallaga | K5: P8 Pejerrey | L5: P9 Poechos | M5: P10 Piura-Cast
A6: OE-01 | B6: 25 | C6: Generar utilidades sostenibles y flujo de caja recurrente | D6: 3 | E6: 3 | F6: 3 | G6: 2 | H6: 2 | I6: 2 | J6: 2 | K6: 2 | L6: 2 | M6: 1
A7: OE-02 | B7: 25 | C7: Incrementar capacidad productiva e infraestructura mayor | D7: 3 | E7: 3 | F7: 3 | G7: 3 | H7: 3 | I7: 2 | J7: 2 | K7: 2 | L7: 2 | M7: 2
A8: OE-03 | B8: 20 | C8: Reducir costos operativos mediante economías de escala | D8: 2 | E8: 2 | F8: 2 | G8: 2 | H8: 2 | I8: 2 | J8: 3 | K8: 2 | L8: 2 | M8: 2
A9: OE-04 | B9: 20 | C9: Diversificar presencia en mercados regionales e intermodales | D9: 3 | E9: 3 | F9: 2 | G9: 3 | H9: 3 | I9: 1 | J9: 1 | K9: 1 | L9: 1 | M9: 1
A10: OE-05 | B10: 15 | C10: Remediación ambiental y sostenibilidad de cuencas hídricas | D10: 2 | E10: 2 | F10: 2 | G10: 2 | H10: 2 | I10: 3 | J10: 2 | K10: 2 | L10: 3 | M10: 3
A11: OE-06 | B11: 15 | C11: Minimizar impacto ambiental en zonas naturales protegidas | D11: 2 | E11: 2 | F11: 2 | G11: 2 | H11: 2 | I11: 3 | J11: 2 | K11: 2 | L11: 3 | M11: 3
A12: OE-07 | B12: 15 | C12: Organización ágil y respuesta inmediata ante emergencias | D12: 3 | E12: 2 | F12: 3 | G12: 2 | H12: 2 | I12: 2 | J12: 3 | K12: 2 | L12: 1 | M12: 2
A13: OE-08 | B13: 15 | C13: Eficiencia en producción y gestión de maquinaria pesada | D13: 3 | E13: 2 | F13: 3 | G13: 2 | H13: 2 | I13: 2 | J13: 3 | K13: 2 | L13: 1 | M13: 2
A14: OE-09 | B14: 15 | C14: Plan de seguridad y salud en el trabajo (cero fatalidades) | D14: 3 | E14: 2 | F14: 3 | G14: 2 | H14: 2 | I14: 2 | J14: 2 | K14: 2 | L14: 2 | M14: 2
A15: OE-10 | B15: 15 | C15: Contratación efectiva de mano de obra local calificada | D15: 2 | E15: 2 | F15: 2 | G15: 2 | H15: 2 | I15: 2 | J15: 2 | K15: 2 | L15: 2 | M15: 2
A16: OE-11 | B16: 15 | C16: Conducta ética certificada bajo norma antisoborno ISO 37001 | D16: 3 | E16: 3 | F16: 3 | G16: 3 | H16: 3 | I16: 3 | J16: 3 | K16: 3 | L16: 3 | M16: 3
A17: OE-12 | B17: 15 | C17: Organización transparente y auditoría abierta con comunidades | D17: 2 | E17: 2 | F17: 2 | G17: 2 | H17: 2 | I17: 2 | J17: 2 | K17: 2 | L17: 2 | M17: 2
... A19: OE-14 | B19: 15 | C19: Oportunidades de ascenso y bienestar social a los colaboradores | D19: 3 | E19: 3 | F19: 2 | G19: 3 | H19: 2 | I19: 3 | J19: 2 | K19: 2 | L19: 3 | M19: 3
A21: TOTAL PESO | B21: =SUM(B6:B19) -> 240 | C21: PUNTAJE PONDERADO FINAL (0 - 3.00) | D21: 2.6 | E21: 2.38 | F21: 2.48 | G21: 2.23 | H21: 2.15 | I21: 2.15 | J21: 2.15 | K21: 2 | L21: 2 | M21: 1.92
A22: FÓRMULA EXACTA | C22: Cálculo dinámico en Excel: | D22: =SUMPRODUCT($B$6:$B$19,D6:D19)/$B$21 -> 2.6666667 | E22: =SUMPRODUCT($B$6:$B$19,E6:E19)/$B$21 -> 2.4791667 | F22: =SUMPRODUCT($B$6:$B$19,F6:F19)/$B$21 -> 2.5208333 | G22: =SUMPRODUCT($B$6:$B$19,G6:G19)/$B$21 -> 2.3125 | H22: =SUMPRODUCT($B$6:$B$19,H6:H19)/$B$21 -> 2.25 | I22: =SUMPRODUCT($B$6:$B$19,I6:I19)/$B$21 -> 2.1666667 | J22: =SUMPRODUCT($B$6:$B$19,J6:J19)/$B$21 -> 2.1875 | K22: =SUMPRODUCT($B$6:$B$19,K6:K19)/$B$21 -> 1.9791667 | ... M22: =SUMPRODUCT($B$6:$B$19,M6:M19)/$B$21 -> 2.0625
A23: RANKING ALINEACIÓN | D23: =RANK(D21,$D$21:$M$21) -> 1 | E23: =RANK(E21,$D$21:$M$21) -> 3 | F23: =RANK(F21,$D$21:$M$21) -> 2 | G23: =RANK(G21,$D$21:$M$21) -> 4 | H23: =RANK(H21,$D$21:$M$21) -> 5 | I23: =RANK(I21,$D$21:$M$21) -> 5 | J23: =RANK(J21,$D$21:$M$21) -> 5 | K23: =RANK(K21,$D$21:$M$21) -> 8 | ... M23: =RANK(M21,$D$21:$M$21) -> 10
A25: ESTADÍSTICAS DEL SCORE DE ALINEACIÓN
A26: Promedio del Portafolio | D26: =AVERAGE(D21:M21) -> 2.206
A27: Puntaje Máximo | D27: =MAX(D21:M21) -> 2.6
A28: Puntaje Mínimo | D28: =MIN(D21:M21) -> 1.92
A29: Desviación Estándar | D29: =_xlfn.STDEV.S(D21:M21) -> 0.22041375
A31: Leyenda
A32: No contribuye | D32: 1
A33: Contribución < 50% del objetivo | D33: 2
A34: Contribución > 50% del objetivo | D34: 3

Sheet 03_Evaluacion_Riesgos
A1: MÓDULO 04: EVALUACIÓN DE RIESGOS DEL PORTAFOLIO CASA | I1: Código: CASA-TP-26
A2: MATRIZ PROBABILIDAD × IMPACTO Y PLAN DE RESPUESTA OPERACIONAL | I2: Fecha: 23/10/2026
A3: ESCALA: BAJA = 1, MEDIA = 2, ALTA = 3. SEVERIDAD = PROBABILIDAD * IMPACTO (1 A 9) | I3: Versión: 01
A4: NIVEL DE RIESGO: CRÍTICO = SEVERIDAD 9 · ALTO = SEVERIDAD 6 · MEDIO = SEVERIDAD ≤ 5 | I4: Página: 3 de 8
A5: ID Riesgo | B5: Título del Riesgo | C5: Causa Raíz y Efecto en Portafolio | D5: Origen | E5: Probabilidad (P) | F5: Impacto (I) | G5: Severidad (P × I) | H5: Nivel de Riesgo | I5: Responsable Designado | J5: Estrategia de Mitigación Validada | K5: Proyectos Afectados
A6: R1 | B6: Disponibilidad Financiera y Aprobaciones MTC | C6: Cambio de prioridades presupuestales del Estado retrasa transferencias de CRPAO y adendas. | D6: Externo | E6: 2 | F6: 3 | G6: =E6*F6 -> 6 | H6: =IF(G6>=9,"Crítico",IF(G6>=6,"Alto","Medio")) -> Alto | I6: Gerente de Portafolio / Concesiones | J6: Estructuración de fideicomisos con banca privada; revisión quincenal de cuentas de fideicomiso. | K6: P1, P3, P4
A7: R2 | B7: Inflación de Insumos Críticos de Construcción | C7: Incremento sostenido en asfalto modificado, acero corrugado y combustible genera sobrecostos. | D7: Externo | E7: 3 | F7: 3 | G7: =E7*F7 -> 9 | H7: =IF(G7>=9,"Crítico",IF(G7>=6,"Alto","Medio")) -> Crítico | I7: Gerencia de Costos y Abastecimiento | J7: Fórmula polinómica con índices INEI; compras mayoristas anticipadas y cobertura de precios. | K7: P1, P2, P3, P4, P6
A8: R3 | B8: Retrasos en Liberación de Predios e Interferencias | C8: Expropiaciones y saneamiento físico-legal demoran entrega de frentes de obra (Caracoto, Trujillo). | D8: Externo | E8: 3 | F8: 3 | G8: =E8*F8 -> 9 | H8: =IF(G8>=9,"Crítico",IF(G8>=6,"Alto","Medio")) -> Crítico | I8: Gerencia Legal & Gestión Predial | J8: Equipo especializado de saneamiento predial directo y convenios de trato directo con propietarios. | K8: P1, P4, P6
A9: R4 | B9: Conflictos Sociales y Relacionamiento Comunitario | C9: Bloqueos y demandas de comunidades locales colindantes paralizan frentes de obra. | D9: Externo | E9: 2 | F9: 3 | G9: =E9*F9 -> 6 | H9: =IF(G9>=9,"Crítico",IF(G9>=6,"Alto","Medio")) -> Alto | I9: Gerencia de Gestión Social y RSE | J9: Mesas de diálogo permanentes, contratación de mano de obra local y proyectos sociales comunitarios. | K9: P2, P4, P6
A10: R5 | B10: Clima Extremo (Fenómeno El Niño y Huaicos) | C10: Lluvias torrenciales en el norte o nevadas en el altiplano destruyen accesos y desbordan ríos. | D10: Externo | E10: 2 | F10: 3 | G10: =E10*F10 -> 6 | H10: =IF(G10>=9,"Crítico",IF(G10>=6,"Alto","Medio")) -> Alto | I10: Gerencia de Obra / SSOMA | J10: Obras de drenaje sobredimensionadas, maquinaria pesada de contingencia y seguros CAR todo riesgo. | K10: P1, P2, P6, P9
A11: R6 | B11: Sobrecarga de Equipos Clave y Residentes | C11: Simultaneidad de frentes de trabajo satura a los ingenieros residentes y maquinaria especializada. | D11: Interno | E11: 3 | F11: 2 | G11: =E11*F11 -> 6 | H11: =IF(G11>=9,"Crítico",IF(G11>=6,"Alto","Medio")) -> Alto | I11: Gerencia de Operaciones | J11: Balance de carga de horas-hombre; escalonamiento de inicios y contratación de 2 residentes adicionales. | K11: P1, P2, P3, P4
A12: R7 | B12: Seguridad Operacional en Frentes Remotos | C12: Trabajos de alta montaña a más de 4,500 msnm o selva aumentan riesgo de incidentes de tránsito. | D12: Interno | E12: 2 | F12: 3 | G12: =E12*F12 -> 6 | H12: =IF(G12>=9,"Crítico",IF(G12>=6,"Alto","Medio")) -> Alto | I12: Jefatura SSOMA | J12: Auditorías de campo semanales, telemetría de velocidad GPS y capacitación en manejo defensivo. | K12: P2, P5, P6
A13: R8 | B13: Interrupciones en la Cadena de Suministro | C13: Dificultad de abastecimiento de cemento y explosivos en zonas aisladas de selva o puna. | D13: Externo | E13: 2 | F13: 2 | G13: =E13*F13 -> 4 | H13: =IF(G13>=9,"Crítico",IF(G13>=6,"Alto","Medio")) -> Medio | I13: Gerencia de Logística | J13: Almacenes de contingencia con stock para 45 días y proveedores alternativos homologados. | K13: P2, P5, P6
A15: TABLA DE EXPOSICIÓN AL RIESGO POR PROYECTO (0 - 3.0)
A16: N° | B16: Proyecto | C16: Score Riesgo | D16: Categoría Riesgo | E16: Justificación de Severidad
A17: 1 | B17: Autopista del Sol | C17: 1.9 | D17: Alto | E17: Exposición a predios no liberados y fenómeno El Niño costero
A18: 2 | B18: Interoceánica Sur T5 | C18: 2.1 | D18: Crítico | E18: Ruta a gran altitud (>4,500 msnm), clima severo e inflación de asfalto
A19: 3 | B19: Red Vial N.º 6 | C19: 1.85 | D19: Alto | E19: Tráfico pesado intenso, mantenimiento preventivo de puentes
A20: 4 | B20: Puno - Juliaca | C20: 1.6 | D20: Medio-Alto | E20: Interferencias urbanas en Caracoto y conflictos sociales altiplánicos
A21: 5 | B21: Terminal Yurimaguas | C21: 1.95 | D21: Alto | E21: Variabilidad del caudal del río Huallaga e interconexión fluvial
A22: 6 | B22: Irrigación Amojao | C22: 1.75 | D22: Medio-Alto | E22: Excavación de túneles en roca deleznable y lluvias en selva alta
A23: 7 | B23: Red Vial Huallaga | C23: 1.5 | D23: Medio | E23: Riesgo de deslizamientos en época de lluvias
A24: 8 | B24: Pampa Pejerrey | C24: 1.3 | D24: Bajo-Medio | E24: Trabajos rutinarios de conservación vial
A25: 9 | B25: Presa Poechos | C25: 1.4 | D25: Medio | E25: Gestión de descargas hídricas durante la construcción
A26: 10 | B26: Agua Potable Piura | C26: 1.2 | D26: Bajo | E26: Interferencias con redes existentes en zonas urbanas
A28: Promedio Riesgo Portafolio | C28: =AVERAGE(C17:C26) -> 1.655

Sheet 04_Scoring_Priorizacion
A1: MÓDULO 07: SELECCIÓN Y PRIORIZACIÓN DEL PORTAFOLIO | K1: Código: CASA-TP-26
A2: MODELO DE SCORING PONDERADO MULTICRITERIO - RESOLUCIÓN DEL COMITÉ | K2: Fecha: 23/10/2026
A3: REGLA DE DECISIÓN: SCORE >= 2.00 (SELECCIONADO) | 1.50 <= SCORE < 2.00 (CONDICIONADO) | SCORE < 1.50 (DIFERIDO) | K3: Versión: 01
K4: Página: 4 de 8
A5: N° | B5: Proyecto | C5: Alineación (AE 30%) | D5: Impacto Cliente (Cli 10%) | E5: Estándares ISO (Est 10%) | F5: Riesgo Controlado (Rsk 20%) | G5: Rentabilidad ROI (ROI 20%) | H5: Viabilidad Costo (Cst 10%) | I5: Score Ponderado Final | J5: Resolución Comité | K5: Ranking Prioridad | L5: Horizonte Contractual
A6: PESOS | C6: 0.3 | D6: 0.1 | E6: 0.1 | F6: 0.2 | G6: 0.2 | H6: 0.1 | I6: =SUM(C6:H6) -> 1
A7: 1 | B7: Autopista del Sol | C7: 3 | D7: 3 | E7: 3 | F7: 2 | G7: 3 | H7: 3 | I7: =C7*$C$6+D7*$D$6+E7*$E$6+F7*$F$6+G7*$G$6+H7*$H$6 -> 2.8 | J7: =IF(I7>=2,"Seleccionado",IF(I7>=1.5,"Condicionado","Diferido")) -> Seleccionado | K7: =RANK(I7,$I$7:$I$16) -> 1 | L7: 25 años (Largo)
A8: 2 | B8: Interoceánica Sur T5 | C8: 3 | D8: 3 | E8: 3 | F8: 2 | G8: 3 | H8: 2 | I8: =C8*$C$6+D8*$D$6+E8*$E$6+F8*$F$6+G8*$G$6+H8*$H$6 -> 2.7 | J8: =IF(I8>=2,"Seleccionado",IF(I8>=1.5,"Condicionado","Diferido")) -> Seleccionado | K8: =RANK(I8,$I$7:$I$16) -> 2 | L8: Largo plazo
A9: 3 | B9: Red Vial N.º 6 | C9: 3 | D9: 2 | E9: 3 | F9: 2 | G9: 3 | H9: 3 | I9: =C9*$C$6+D9*$D$6+E9*$E$6+F9*$F$6+G9*$G$6+H9*$H$6 -> 2.7 | J9: =IF(I9>=2,"Seleccionado",IF(I9>=1.5,"Condicionado","Diferido")) -> Seleccionado | K9: =RANK(I9,$I$7:$I$16) -> 2 | L9: 25 años (Largo)
A10: 4 | B10: Segunda Calzada Puno-Juliaca | C10: 3 | D10: 3 | E10: 2 | F10: 1 | G10: 2 | H10: 2 | I10: =C10*$C$6+D10*$D$6+E10*$E$6+F10*$F$6+G10*$G$6+H10*$H$6 -> 2.2 | J10: =IF(I10>=2,"Seleccionado",IF(I10>=1.5,"Condicionado","Diferido")) -> Seleccionado | K10: =RANK(I10,$I$7:$I$16) -> 4 | L10: Mediano plazo
A11: 5 | B11: Terminal Portuario Yurimaguas | C11: 2 | D11: 3 | E11: 2 | F11: 2 | G11: 2 | H11: 2 | I11: =C11*$C$6+D11*$D$6+E11*$E$6+F11*$F$6+G11*$G$6+H11*$H$6 -> 2.1 | J11: =IF(I11>=2,"Seleccionado",IF(I11>=1.5,"Condicionado","Diferido")) -> Seleccionado | K11: =RANK(I11,$I$7:$I$16) -> 5 | L11: Largo plazo
A12: 6 | B12: Obras de Irrigación Amojao | C12: 2 | D12: 2 | E12: 3 | F12: 2 | G12: 2 | H12: 2 | I12: =C12*$C$6+D12*$D$6+E12*$E$6+F12*$F$6+G12*$G$6+H12*$H$6 -> 2.1 | J12: =IF(I12>=2,"Seleccionado",IF(I12>=1.5,"Condicionado","Diferido")) -> Seleccionado | K12: =RANK(I12,$I$7:$I$16) -> 5 | L12: Mediano plazo
A13: 7 | B13: Red Vial Huallaga | C13: 2 | D13: 3 | E13: 2 | F13: 2 | G13: 2 | H13: 2 | I13: =C13*$C$6+D13*$D$6+E13*$E$6+F13*$F$6+G13*$G$6+H13*$H$6 -> 2.1 | J13: =IF(I13>=2,"Seleccionado",IF(I13>=1.5,"Condicionado","Diferido")) -> Seleccionado | K13: =RANK(I13,$I$7:$I$16) -> 5 | L13: Mediano plazo
A14: 8 | B14: Conservación P. Pejerrey | C14: 2 | D14: 2 | E14: 2 | F14: 1 | G14: 2 | H14: 1 | I14: =C14*$C$6+D14*$D$6+E14*$E$6+F14*$F$6+G14*$G$6+H14*$H$6 -> 1.7 | J14: =IF(I14>=2,"Seleccionado",IF(I14>=1.5,"Condicionado","Diferido")) -> Condicionado | K14: =RANK(I14,$I$7:$I$16) -> 8 | L14: Corto plazo
A15: 9 | B15: Presa Poechos (Cuenco) | C15: 2 | D15: 3 | E15: 2 | F15: 1 | G15: 1 | H15: 2 | I15: =C15*$C$6+D15*$D$6+E15*$E$6+F15*$F$6+G15*$G$6+H15*$H$6 -> 1.7 | J15: =IF(I15>=2,"Seleccionado",IF(I15>=1.5,"Condicionado","Diferido")) -> Condicionado | K15: =RANK(I15,$I$7:$I$16) -> 9 | L15: Corto plazo
A16: 10 | B16: Agua Potable Piura-Castilla | C16: 1 | D16: 2 | E16: 2 | F16: 1 | G16: 1 | H16: 1 | I16: =C16*$C$6+D16*$D$6+E16*$E$6+F16*$F$6+G16*$G$6+H16*$H$6 -> 1.2 | J16: =IF(I16>=2,"Seleccionado",IF(I16>=1.5,"Condicionado","Diferido")) -> Diferido | K16: =RANK(I16,$I$7:$I$16) -> 10 | L16: Corto plazo
A18: RESUMEN DE DICTAMEN DEL COMITÉ
B19: Proyectos Seleccionados (>= 2.00) | C19: =COUNTIF(J7:J16,"Seleccionado") -> 7 | D19: =C19&" proyectos autorizados inmediatamente" -> 7 proyectos autorizados inmediatamente
B20: Proyectos Condicionados (1.50 - 1.99) | C20: =COUNTIF(J7:J16,"Condicionado") -> 2 | D20: =C20&" proyectos sujetos a disponibilidad de fondos" -> 2 proyectos sujetos a disponibilidad de fondos
B21: Proyectos Diferidos (< 1.50) | C21: =COUNTIF(J7:J16,"Diferido") -> 1 | D21: =C21&" proyecto diferido para el siguiente ciclo" -> 1 proyecto diferido para el siguiente ciclo

Sheet 05_Matriz_AHP
A1: MÓDULO 07: MATRIZ DE COMPARACIÓN POR PARES AHP (TOP 6 PROYECTOS) | J1: Código: CASA-TP-26
A2: MÉTODO DE JERARQUÍA ANALÍTICA (SAATY) / DOMINANCIA BINARIA | J2: Fecha: 23/10/2026
A3: CRITERIO: 1 = PROYECTO FILA DOMINA O TIENE MAYOR PRIORIDAD QUE COLUMNA, 0 = CASO CONTRARIO | J3: Versión: 01
J4: Página: 5 de 8
A5: Código | B5: Proyecto | C5: A. Sol | D5: B. IIRSA | E5: C. RV6 | F5: D. Puno-Jul | G5: E. Yurimag | H5: F. Amojao | I5: Total Dominancia | J5: Prioridad Relativa | K5: Vector Normalizado
A6: A | B6: Autopista del Sol | D6: 1 | E6: 1 | F6: 1 | G6: 1 | H6: 1 | I6: =SUM(C6:H6) -> 5 | J6: P1 (Prioridad 1) | K6: =I6/SUM($I$6:$I$11) -> 0.33333333
A7: B | B7: Interoceánica Sur T5 | C7: 0 | E7: 1 | F7: 1 | G7: 1 | H7: 1 | I7: =SUM(C7:H7) -> 4 | J7: P2 (Prioridad 2) | K7: =I7/SUM($I$6:$I$11) -> 0.26666667
A8: C | B8: Red Vial N.º 6 | C8: 0 | D8: 0 | F8: 1 | G8: 1 | H8: 1 | I8: =SUM(C8:H8) -> 3 | J8: P3 (Prioridad 3) | K8: =I8/SUM($I$6:$I$11) -> 0.2
A9: D | B9: Segunda Calzada Puno-Juliaca | C9: 0 | D9: 0 | E9: 0 | G9: 1 | H9: 1 | I9: =SUM(C9:H9) -> 2 | J9: P4 (Prioridad 4) | K9: =I9/SUM($I$6:$I$11) -> 0.13333333
A10: E | B10: Terminal Portuario Yurimaguas | C10: 0 | D10: 0 | E10: 0 | F10: 0 | H10: 1 | I10: =SUM(C10:H10) -> 1 | J10: P5 (Prioridad 5) | K10: =I10/SUM($I$6:$I$11) -> 0.066666667
A11: F | B11: Obras de Irrigación Amojao | C11: 0 | D11: 0 | E11: 0 | F11: 0 | G11: 0 | I11: =SUM(C11:H11) -> 0 | J11: P6 (Prioridad 6) | K11: =I11/SUM($I$6:$I$11) -> 0
A12: TOTAL | I12: =SUM(I6:I11) -> 15 | K12: =SUM(K6:K11) -> 1

Sheet 06_Capacidad_y_Balance
A1: MÓDULO 08: GESTIÓN DE RECURSOS HUMANOS Y BALANCE DE CAPACIDAD (HH) | F1: Código: CASA-TP-26 · Versión: 01
A2: SUPUESTO METODOLÓGICO: 132 HORAS PRODUCTIVAS EFECTIVAS / PERSONA-MES ((8H - 2H INDIRECTAS) × 22 DÍAS LABORABLES) | F2: Fecha: 23/10/2026
F3: Página: 6 de 8
A4: TABLA 01: DISPONIBILIDAD POR PERFIL PROFESIONAL
A5: Perfil Profesional | B5: Tipo Dotación | C5: Jornada (h/día) | D5: Horas Efectivas/día | E5: Horas-Hombre / Mes
A6: Gerentes Senior | B6: Interno | C6: 8 | D6: 5.95 | E6: =D6*$B$11 -> 130.9
A7: Administrativo | B7: Interno | C7: 8 | D7: 4.95 | E7: =D7*$B$11 -> 108.9
A8: Ingeniería & Campo | B8: Interno | C8: 8 | D8: 3.95 | E8: =D8*$B$11 -> 86.9
A9: Especialistas SSOMA | B9: Externo | C9: 8 | D9: 3.95 | E9: =D9*$B$11 -> 86.9
A10: QA / QC Calidad | B10: Externo | C10: 8 | D10: 3.95 | E10: =D10*$B$11 -> 86.9
A11: Días laborables por mes (supuesto de la nota de arriba) | B11: 22
A12: TABLA 02: BALANCE DE CAPACIDAD VS DEMANDA (DOTACIÓN DE 25 PROFESIONALES)
A13: Rol Técnico de Obra | B13: N° Personas | C13: Horas/Mes por Persona | D13: Capacidad Disp. (h/mes) | E13: Demanda Operativa (h/mes) | F13: Brecha Operativa (h/mes) | G13: Estado de Capacidad
A14: Residente de Obra | B14: 6 | C14: 132 | D14: =B14*C14 -> 792 | E14: 924 | F14: =D14-E14 -> -132 | G14: =IF(F14<0,"Sobrecarga Crítica","Adecuado") -> Sobrecarga Crítica
A15: Planificación y Control | B15: 4 | C15: 132 | D15: =B15*C15 -> 528 | E15: 480 | F15: =D15-E15 -> 48 | G15: =IF(F15<0,"Sobrecarga","Adecuado") -> Adecuado
A16: Costos y Valorizaciones | B16: 4 | C16: 132 | D16: =B16*C16 -> 528 | E16: 500 | F16: =D16-E16 -> 28 | G16: =IF(F16<0,"Sobrecarga","Adecuado") -> Adecuado
A17: Especialistas SSOMA | B17: 6 | C17: 132 | D17: =B17*C17 -> 792 | E17: 850 | F17: =D17-E17 -> -58 | G17: =IF(F17<0,"Sobrecarga Crítica","Adecuado") -> Sobrecarga Crítica
A18: Gestión Social y Ambiental | B18: 5 | C18: 132 | D18: =B18*C18 -> 660 | E18: 700 | F18: =D18-E18 -> -40 | G18: =IF(F18<0,"Ajuste Necesario","Adecuado") -> Ajuste Necesario
A19: TOTALES CONSOLIDADOS | B19: =SUM(B14:B18) -> 25 | D19: =SUM(D14:D18) -> 3300 | E19: =SUM(E14:E18) -> 3454 | F19: =SUM(F14:F18) -> -154 | G19: =F19/D19 -> -0.046666667
A21: ANÁLISIS COMPARATIVO DE ESCENARIOS DE DEMANDA VS CAPACIDAD
A22: Escenario Analizado | B22: Demanda Horas (h/mes) | C22: Capacidad Horas (h/mes) | D22: Déficit / Superávit (h/mes) | E22: Diagnóstico Operativo
A23: Escenario 1: Solo P1-P3 (Concesiones) | B23: 4389 | C23: 1068 | D23: =C23-B23 -> -3321 | E23: Déficit masivo sin contratación externa
A24: Escenario 2: Todos los 10 Proyectos | B24: 8046 | C24: 1068 | D24: =C24-B24 -> -6978 | E24: Inviable con la dotación actual
A25: Escenario 3: Solo Estratégicos (P1-P5) | B25: 5852 | C25: 1068 | D25: =C25-B25 -> -4784 | E25: Requiere tercerización de frentes
A26: Capacidad Balanceada Recomendada | B26: 6346 | C26: 6346 | D26: =C26-B26 -> 0 | E26: Equilibrio 100% mediante +2 Residentes y +1 SSOMA

Sheet 07_Cronograma_Gantt
A1: MÓDULO 09: PLAN MAESTRO DEL PORTAFOLIO Y CRONOGRAMA GANTT 2026 - 2034 | K1: Código: CASA-TP-26 · Versión: 01
A2: CRONOGRAMA DE EJECUCIÓN, CONCESIONES Y GOBERNANZA | K2: Fecha: 23/10/2026
K3: Página: 7 de 8
A4: N° | B4: Proyecto | C4: Categoría | D4: 2026 | E4: 2027 | F4: 2028 | G4: 2029 | H4: 2030 | I4: 2031 | J4: 2032 | K4: 2033 | L4: 2034 | M4: Hito Principal de Cierre
A5: 1 | B5: Autopista del Sol | C5: Estratégico | D5: Operación | E5: Operación | F5: Operación | G5: Operación | H5: Operación | I5: Operación | J5: Operación | K5: Operación | L5: Reversión MTC | M5: Transferencia Concesión 25 Años
A6: 2 | B6: Interoceánica Sur T5 | C6: Estratégico | D6: Concluido | E6: Liquidado | F6: Garantía | G6: - | H6: - | I6: - | J6: - | K6: - | L6: - | M6: Acta de Recepción Provías
A7: 3 | B7: Red Vial N.º 6 | C7: Estratégico | D7: Operación | E7: Operación | F7: Operación | G7: Operación | H7: Operación | I7: Reversión | J7: - | K7: - | L7: - | M7: Cierre Contractual COVIPERÚ
A8: 4 | B8: Puno - Juliaca | C8: Estratégico | D8: Construcción | E8: Entrega 19km | F8: Construcción | G8: Entrega 50km | H8: Garantía | I8: - | J8: - | K8: - | L8: - | M8: Culminación Segunda Calzada
A9: 5 | B9: Terminal Yurimaguas | C9: Estratégico | D9: Operación | E9: Operación | F9: Operación | G9: Operación | H9: Operación | I9: Operación | J9: Operación | K9: Operación | L9: Operación | M9: Concesión 30 Años APN
A10: 6 | B10: Irrigación Amojao | C10: Sostenibilidad | D10: Túnel Chiriaco | E10: Canal Principal | F10: Entrega 10kha | G10: Liquidación | H10: - | I10: - | J10: - | K10: - | L10: - | M10: Acta Entrega Juntas de Usuarios
A11: 7 | B11: Red Vial Huallaga | C11: Táctico | D11: Concluido | E11: Liquidado | F11: - | G11: - | H11: - | I11: - | J11: - | K11: - | L11: - | M11: Cumplimiento Niveles de Servicio
A12: 8 | B12: Pampa Pejerrey | C12: Táctico | D12: Concluido | E12: - | F12: - | G12: - | H12: - | I12: - | J12: - | K12: - | L12: - | M12: Acta de Conformidad Provías
A13: 9 | B13: Presa Poechos | C13: Sostenibilidad | D13: Concluido | E13: Operación | F13: - | G13: - | H13: - | I13: - | J13: - | K13: - | L13: - | M13: Protección Hídrica Piura
A14: 10 | B14: Agua Potable Piura | C14: Sostenibilidad | D14: Concluido | E14: Operación | F14: - | G14: - | H14: - | I14: - | J14: - | K14: - | L14: - | M14: Servicio Continuo 250k hab.
A16: HITOS PRINCIPALES DE GOBERNANZA
A17: Año | B17: Hito Contractual / Operativo | C17: Proyecto Afectado | D17: Entidad / Responsable | G17: Entregable Validado
A18: 2026 | B18: Autorización Formal del Portafolio y Asignación de Recursos | C18: Todos los 10 | D18: Comité de Inversiones / Directorio CASA | G18: Acta de Aprobación de Carta Fundacional
A19: 2026 | B19: Inicio Fase de Construcción Irrigación Amojao II - III | C19: P6 Amojao | D19: Gerencia de Irrigación CASA / PEJSIB | G19: Expediente Técnico Aprobado MINAGRI
A20: 2027 | B20: Entrega de 19 km de Segunda Calzada Puno - Juliaca | C20: P4 Puno-Juliaca | D20: Gerencia Zonal Sur CASA | G20: Tramo Asfaltado Operativo y Señalizado
A21: 2028 | B21: Culminación Integral Amojao - 10,000 ha Irrigadas | C21: P6 Amojao | D21: PEJSIB / CASA Contratistas | G21: Acta de Entrega a Juntas de Usuarios
A22: 2029 | B22: Finalización de los 50 km Segunda Calzada Puno-Juliaca | C22: P4 Puno-Juliaca | D22: Gerencia Zonal Sur CASA | G22: Acta de Recepción Provías Nacional
A23: 2031 | B23: Cierre y Reversión de Concesión Red Vial N.º 6 | C23: P3 Red Vial 6 | D23: Gerencia de Concesiones / COVIPERÚ | G23: Transferencia Contractual MTC / OSITRAN
A24: 2034 | B24: Fin de Concesión Autopista del Sol (25 Años) | C24: P1 Autopista del Sol | D24: Gerencia General CASA / COVISOL | G24: Transferencia Definitiva al Estado Peruano

Sheet 08_Estadisticas_Graficos
A1: MÓDULO DE SOPORTE: SERIES Y DATOS DE TODOS LOS GRÁFICOS ESTADÍSTICOS | D1: Código: CASA-TP-26 · Versión: 01
A2: ESTA HOJA CONTIENE LAS TABLAS EXACTAS UTILIZADAS POR CHART.JS EN LA APLICACIÓN WEB | D2: Fecha: 23/10/2026
D3: Página: 8 de 8 | G3: GALERÍA DE GRÁFICOS ESTADÍSTICOS (VINCULADOS A LAS TABLAS DE ESTA HOJA)
A4: GRÁFICO 01: INVERSIÓN TOTAL POR CATEGORÍA (BARRAS Y TORTA)
A5: Categoría | B5: Inversión (S/ Millones) | C5: % Participación | D5: Etiqueta del gráfico
A6: Estratégicos | B6: ='01_Resumen_Portafolio'!D31/10^6 -> 3230 | C6: ='01_Resumen_Portafolio'!E31 -> 0.88876048 | D6: =A6&" (S/ "&TEXT(B6,"#,##0")&" M)" -> Estratégicos (S/ 3,230 M)
A7: Sostenibilidad | B7: ='01_Resumen_Portafolio'!D32/10^6 -> 362.275 | C7: ='01_Resumen_Portafolio'!E32 -> 0.09968288 | D7: =A7&" (S/ "&TEXT(B7,"#,##0")&" M)" -> Sostenibilidad (S/ 362 M)
A8: Tácticos | B8: ='01_Resumen_Portafolio'!D33/10^6 -> 42 | C8: ='01_Resumen_Portafolio'!E33 -> 0.011556638 | D8: =A8&" (S/ "&TEXT(B8,"#,##0")&" M)" -> Tácticos (S/ 42 M)
A9: TOTAL | B9: =SUM(B6:B8) -> 3634.275 | C9: =SUM(C6:C8) -> 1
A11: GRÁFICO 02: PUNTAJE DE ALINEACIÓN ESTRATÉGICA POR PROYECTO (BARRAS)
A12: Proyecto | B12: Puntaje Ponderado (1 - 3.00)
A13: P1 Autopista del Sol | B13: ='02_Alineacion_Estrategica'!D21 -> 2.6
A14: P2 Interoceánica T5 | B14: ='02_Alineacion_Estrategica'!E21 -> 2.38
A15: P3 Red Vial N°6 | B15: ='02_Alineacion_Estrategica'!F21 -> 2.48
A16: P4 Puno-Juliaca | B16: ='02_Alineacion_Estrategica'!G21 -> 2.23
A17: P5 TP Yurimaguas | B17: ='02_Alineacion_Estrategica'!H21 -> 2.15
A18: P6 Irrigación Amojao | B18: ='02_Alineacion_Estrategica'!I21 -> 2.15
A19: P7 Red Vial Huallaga | B19: ='02_Alineacion_Estrategica'!J21 -> 2.15
A20: P8 Conservación Pejerrey | B20: ='02_Alineacion_Estrategica'!K21 -> 2
A21: P9 Presa Poechos | B21: ='02_Alineacion_Estrategica'!L21 -> 2
A22: P10 Agua Potable Piura | B22: ='02_Alineacion_Estrategica'!M21 -> 1.92
A24: GRÁFICO 03: PERFIL MULTICRITERIO RADAR (TOP 4 PROYECTOS)
A25: Dimensión Evaluada | B25: P1 Autopista | C25: P2 IIRSA T5 | D25: P3 Red Vial 6 | E25: P6 Amojao
A26: Alineación Estratégica | B26: ='04_Scoring_Priorizacion'!C7 -> 3 | C26: ='04_Scoring_Priorizacion'!C8 -> 3 | D26: ='04_Scoring_Priorizacion'!C9 -> 3 | E26: ='04_Scoring_Priorizacion'!C12 -> 2
A27: Riesgo Controlado | B27: ='04_Scoring_Priorizacion'!F7 -> 2 | C27: ='04_Scoring_Priorizacion'!F8 -> 2 | D27: ='04_Scoring_Priorizacion'!F9 -> 2 | E27: ='04_Scoring_Priorizacion'!F12 -> 2
A28: ROI / Retorno Financiero | B28: ='04_Scoring_Priorizacion'!G7 -> 3 | C28: ='04_Scoring_Priorizacion'!G8 -> 3 | D28: ='04_Scoring_Priorizacion'!G9 -> 3 | E28: ='04_Scoring_Priorizacion'!G12 -> 2
A29: Costo / Presupuesto | B29: ='04_Scoring_Priorizacion'!H7 -> 3 | C29: ='04_Scoring_Priorizacion'!H8 -> 2 | D29: ='04_Scoring_Priorizacion'!H9 -> 3 | E29: ='04_Scoring_Priorizacion'!H12 -> 2
A30: Impacto en Cliente / Estado | B30: ='04_Scoring_Priorizacion'!D7 -> 3 | C30: ='04_Scoring_Priorizacion'!D8 -> 3 | D30: ='04_Scoring_Priorizacion'!D9 -> 2 | E30: ='04_Scoring_Priorizacion'!D12 -> 2
A31: Estándares / Calidad ISO | B31: ='04_Scoring_Priorizacion'!E7 -> 3 | C31: ='04_Scoring_Priorizacion'!E8 -> 3 | D31: ='04_Scoring_Priorizacion'!E9 -> 3 | E31: ='04_Scoring_Priorizacion'!E12 -> 3
A33: GRÁFICO 04: DISPERSIÓN SCATTER (ALINEACIÓN VS EXPOSICIÓN AL RIESGO)
A34: Proyecto | B34: Coordenada X (Alineación) | C34: Coordenada Y (Riesgo)
A35: P1 Autopista del Sol | B35: ='02_Alineacion_Estrategica'!D21 -> 2.6 | C35: ='03_Evaluacion_Riesgos'!C17 -> 1.9
A36: P2 Interoceánica Sur T5 | B36: ='02_Alineacion_Estrategica'!E21 -> 2.38 | C36: ='03_Evaluacion_Riesgos'!C18 -> 2.1
A37: P3 Red Vial N.º 6 | B37: ='02_Alineacion_Estrategica'!F21 -> 2.48 | C37: ='03_Evaluacion_Riesgos'!C19 -> 1.85
A38: P4 Segunda Calzada Puno-Juliaca | B38: ='02_Alineacion_Estrategica'!G21 -> 2.23 | C38: ='03_Evaluacion_Riesgos'!C20 -> 1.6
A39: P5 Terminal Portuario Yurimaguas | B39: ='02_Alineacion_Estrategica'!H21 -> 2.15 | C39: ='03_Evaluacion_Riesgos'!C21 -> 1.95
A40: P6 Obras de Irrigación Amojao | B40: ='02_Alineacion_Estrategica'!I21 -> 2.15 | C40: ='03_Evaluacion_Riesgos'!C22 -> 1.75
A41: P7 Red Vial Huallaga | B41: ='02_Alineacion_Estrategica'!J21 -> 2.15 | C41: ='03_Evaluacion_Riesgos'!C23 -> 1.5
A42: P8 Conservación P. Pejerrey | B42: ='02_Alineacion_Estrategica'!K21 -> 2 | C42: ='03_Evaluacion_Riesgos'!C24 -> 1.3
A43: P9 Presa Poechos (Cuenco) | B43: ='02_Alineacion_Estrategica'!L21 -> 2 | C43: ='03_Evaluacion_Riesgos'!C25 -> 1.4
...
